<?xml version="1.0" encoding="UTF-8"?>
<testng-results skipped="0" failed="1" ignored="0" total="1" passed="0">
  <reporter-output>
  </reporter-output>
  <suite name="Default suite" duration-ms="74" started-at="2019-03-14T15:43:34Z" finished-at="2019-03-14T15:43:34Z">
    <groups>
    </groups>
    <test name="Default test" duration-ms="74" started-at="2019-03-14T15:43:34Z" finished-at="2019-03-14T15:43:34Z">
      <class name="com.testng.TestClass0001">
        <test-method status="FAIL" signature="testA()[pri:0, instance:com.testng.TestClass0001@1a3869f4]" name="testA" duration-ms="22" started-at="2019-03-14T15:43:34Z" finished-at="2019-03-14T15:43:34Z">
          <exception class="java.lang.AssertionError">
            <message>
              <![CDATA[Failed intentionally
/ by zero]]>
            </message>
            <full-stacktrace>
              <![CDATA[java.lang.AssertionError: Failed intentionally
/ by zero
at org.testng.Assert.fail(Assert.java:96)
at com.testng.TestClass0001.testA(TestClass0001.java:17)
at sun.reflect.NativeMethodAccessorImpl.invoke0(Native Method)
at sun.reflect.NativeMethodAccessorImpl.invoke(Unknown Source)
at sun.reflect.DelegatingMethodAccessorImpl.invoke(Unknown Source)
at java.lang.reflect.Method.invoke(Unknown Source)
at org.testng.internal.MethodInvocationHelper.invokeMethod(MethodInvocationHelper.java:124)
at org.testng.internal.Invoker.invokeMethod(Invoker.java:583)
at org.testng.internal.Invoker.invokeTestMethod(Invoker.java:719)
at org.testng.internal.Invoker.invokeTestMethods(Invoker.java:989)
at org.testng.internal.TestMethodWorker.invokeTestMethods(TestMethodWorker.java:125)
at org.testng.internal.TestMethodWorker.run(TestMethodWorker.java:109)
at org.testng.TestRunner.privateRun(TestRunner.java:648)
at org.testng.TestRunner.run(TestRunner.java:505)
at org.testng.SuiteRunner.runTest(SuiteRunner.java:455)
at org.testng.SuiteRunner.runSequentially(SuiteRunner.java:450)
at org.testng.SuiteRunner.privateRun(SuiteRunner.java:415)
at org.testng.SuiteRunner.run(SuiteRunner.java:364)
at org.testng.SuiteRunnerWorker.runSuite(SuiteRunnerWorker.java:52)
at org.testng.SuiteRunnerWorker.run(SuiteRunnerWorker.java:84)
at org.testng.TestNG.runSuitesSequentially(TestNG.java:1208)
at org.testng.TestNG.runSuitesLocally(TestNG.java:1137)
at org.testng.TestNG.runSuites(TestNG.java:1049)
at org.testng.TestNG.run(TestNG.java:1017)
at org.testng.remote.AbstractRemoteTestNG.run(AbstractRemoteTestNG.java:115)
at org.testng.remote.RemoteTestNG.initAndRun(RemoteTestNG.java:251)
at org.testng.remote.RemoteTestNG.main(RemoteTestNG.java:77)
]]>
            </full-stacktrace>
          </exception> <!-- java.lang.AssertionError -->
          <reporter-output>
          </reporter-output>
        </test-method> <!-- testA -->
        <test-method status="PASS" signature="afterMethod(org.testng.ITestResult)[pri:0, instance:com.testng.TestClass0001@1a3869f4]" name="afterMethod" is-config="true" duration-ms="7" started-at="2019-03-14T15:43:34Z" finished-at="2019-03-14T15:43:34Z">
          <params>
            <param index="0">
              <value>
                <![CDATA[[TestResult name=testA status=FAILURE method=TestClass0001.testA()[pri:0, instance:com.testng.TestClass0001@1a3869f4] output={null}]]]>
              </value>
            </param>
          </params>
          <reporter-output>
          </reporter-output>
        </test-method> <!-- afterMethod -->
      </class> <!-- com.testng.TestClass0001 -->
    </test> <!-- Default test -->
  </suite> <!-- Default suite -->
</testng-results>
